Workbook

Sheet System Control & Outputs
V1: For scaling analysis | W1: https://docs.google.com/spreadsheets/d/191RcAXFUTVjO1Yj8pIApGUdlY5XdXoPTQzPs4sHK86U/edit#gid=730945074
B2: MAIN INPUTS | F2: OUTPUTS | L2: Investment Input Variables | O2: Value | Q2: MINIMUM REVENUE & PROFIT NEEDED | V2: # of Ponds (n) | W2: Capacity (tons/yr) | X2: Volume (m3) | Y2: CAPEX ($M) | Z2: OPEX ($M) | AA2: Min ASP ($/ton) | AB2: Revenue ($M/yr) | AC2: Profit ($M/yr)
Q3: Net Profit Goal ($/yr) | R3: Gross (Pre-Tax) Profit ($/yr) | S3: Revenue Required ($/yr) | V3: =G13 -> 69 | W3: =G5 -> 810.81145 | X3: =G19 -> 32788.913 | Y3: =G45/1000000 -> 20.973661 | Z3: =N23/1000000 -> 10.146194 | AA3: =Q9 -> 28859.922 | AB3: =S5/1000000 -> 23.399955 | AC3: =Q5/1000000 -> 10.086577
B4: Main System Input Variables | C4: Value | D4: Notes | F4: Main System Output Variables | G4: Value | S4: Low | T4: High
B5: Desired Output (tons BM/yr) | C5: 800 | D5: controls overall size of system | F5: Total Biomass Produced (tons/yr) | G5: ='Sys Volume & Area'!D23 -> 810.81145 | Q5: =O9 -> 10086577 | R5: =Q5*(1+C39) -> 13253762 | S5: =R5+N23 -> 23399955 | T5: =R5+O23 -> 24348955
B6: Active Time (days/yr) | C6: 330 | D6: arbitrarily set, seems to be a rough standard | F6: Total Land Area Used (acres) | G6: ='Sys Volume & Area'!E23 -> 78.634471
B7: Pond Size (acres) | C7: 1 | D7: arbitrarily set, seems to be a rough standard, 2.5 acres | F7: Total Land Area Used (hectares) | G7: =G6/2.5 -> 31.453788 | Q7: Minimum Biomass Sale Price ($/ton) | S7: Net Profit Margin (%)
B8: Pond Depth (m) | C8: 0.12 | D8: from computational model, 1.70 is highest productivity | F8: System Productivity (g/m2/day) | G8: =(G5*1000*1000)/(G20*365) -> 6.9806499 | Q8: Low | R8: High | S8: Low | T8: High
B9: Pond LW Ratio (-) | C9: 10 | D9: arbitrarily set, seems to be a rough standard | F9: CO2 Fixation (tons/acre/yr) | G9: =$G$5*'Water & Nutrient Calcs'!$H$11*'Water & Nutrient Calcs'!$F$11/('Water & Nutrient Calcs'!$C$11*G6) -> 20.402515 | L9: Net Profit Goal (USD/yr, net profit supports 1.5X capacity & 1yr of OPS every 5yrs) | O9: =((H45*1.5)+O23)/5 -> 10086577 | Q9: =S5/$G$5 -> 28859.922 | R9: =T5/$G$5 -> 30030.354 | S9: =Q5/S5 -> 0.43105111 | T9: =R5/T5 -> 0.54432568
B10: Pond Spacing (btwn columns, m) | C10: =(3.7/2)+0.75 -> 2.6 | D10: chosen based on equipment need & vehicle movement | F10: CO2 Fixation (tons/hectare/yr) | G10: =$G$5*'Water & Nutrient Calcs'!$H$11*'Water & Nutrient Calcs'!$F$11/('Water & Nutrient Calcs'!$C$11*G7) -> 51.006288 | L10: Min Investment Required (CAPEX + 2yrs of OPEX) | O10: =G45+(2*N23) -> 41266048 | Q10: Current Spirulina Market ASP ($/ton) | S10: 5000
B11: Pond Spacing (btwn rows, m) | C11: =3.7/2 -> 1.85 | D11: chosen based on need for vehicle movement | F11: CO2 Fixation (tons/yr) | G11: =G9*G6 -> 1604.341 | L11: Max Investment Required (CAPEX + 2yrs of OPEX) | O11: =H45+(2*O23) -> 48415514 | Q11: TEA Sale Price Error | S11: =(Q9-$S10)/$S10 -> 4.7719844 | T11: =(R9-$S10)/$S10 -> 5.0060709 | U11: =AVERAGE(S11:T11) -> 4.8890276
B12: Unit Lifetime (yrs) | C12: 30 | D12: arbitrarily set, seems pretty conservative | F12: CO2 Fixation (tons/ton biomass) | G12: =G11/G5 -> 1.9786857
F13: # of Ponds | G13: ='Sys Volume & Area'!E17 -> 69 | L13: Non-technical Input Variables | M13: Factor of Biomass Produced | N13: Cost ($/year) | Q13: REVENUE & PROFIT CALCULATIONS
B14: Growth Input Variables | C14: Value | D14: Notes | F14: Other System Output Variables | G14: Value | H14: Notes | N14: Low | O14: High | Q14: MBSP ($/ton) | R14: Net Profit ($/yr) | T14: Gross (Pre-Tax) Profit ($/yr) | V14: Revenue ($/yr) | X14: Net Profit Margin (%)
B15: Effective Growth Rate (/day) | C15: 0.207 | D15: from computational model, 0.207 is highest productivity | F15: Pond Length (m) | G15: =G16*C9 -> 201.16809 | L15: Quality | M15: 100 | N15: =$M15*$G$5 -> 81081.145 | O15: =$M15*$G$5 -> 81081.145 | R15: Low | S15: High | T15: Low | U15: High | V15: Low | W15: High | X15: Low | Y15: High
B16: Density @ Daily Harvest (g/L) | C16: 0.362 | D16: from computational model, 0.362 is highest productivity | F16: Pond Width (m) | G16: =sqrt((C7*4046.86)/C9) -> 20.116809 | L16: Regulatory | M16: 50 | N16: =$M16*$G$5 -> 40540.573 | O16: =$M16*$G$5 -> 40540.573 | Q16: 2000 | R16: =T16*(1-$C$39) -> -5847855.5 | S16: =U16*(1-$C$39) -> -6498869.5 | T16: =V16-$N$23 -> -8524570.6 | U16: =W16-$O$23 -> -9473570.6 | V16: =Q16*$G$5 -> 1621622.9 | W16: =V16 -> 1621622.9 | X16: =R16/V16 -> -3.6061747 | Y16: =S16/W16 -> -4.007633
F17: Pond Surface Area (m2) | G17: =(G16*(G15-G16))+((pi()/4)*G16^2) -> 3960.0136 | H17: used only to calculate pond volume | L17: Marketing | M17: 100 | N17: =$M17*$G$5 -> 81081.145 | O17: =$M17*$G$5 -> 81081.145 | Q17: =Q16+2000 -> 4000 | R17: =T17*(1-$C$39) -> -4735422.1 | S17: =U17*(1-$C$39) -> -5386436.1 | T17: =V17-$N$23 -> -6902947.7 | U17: =W17-$O$23 -> -7851947.7 | V17: =Q17*$G$5 -> 3243245.8 | W17: =V17 -> 3243245.8 | X17: =R17/V17 -> -1.4600873 | Y17: =S17/W17 -> -1.6608165
B18: Operation Input Variables | C18: Cost | D18: Notes | F18: Pond Volume (m3) | G18: =C8*G17 -> 475.20164 | H18: used to calculate # of ponds needed | L18: Sales | M18: 50 | N18: =$M18*$G$5 -> 40540.573 | O18: =$M18*$G$5 -> 40540.573 | Q18: =Q17+2000 -> 6000 | R18: =T18*(1-$C$39) -> -3622988.8 | S18: =U18*(1-$C$39) -> -4274002.8 | T18: =V18-$N$23 -> -5281324.8 | U18: =W18-$O$23 -> -6230324.8 | V18: =Q18*$G$5 -> 4864868.7 | W18: =V18 -> 4864868.7 | X18: =R18/V18 -> -0.74472489 | Y18: =S18/W18 -> -0.87854433
B19: Electricity Power ($/kWh) | C19: 0.4024 | D19: Hawaii 2022, medium power use business | F19: System Volume (m3) | G19: =G18*'Sys Volume & Area'!E17 -> 32788.913 | L19: Total | M19: =SUM(M15:M18) -> 300 | N19: =SUM(N15:N18) -> 243243.44 | O19: =SUM(O15:O18) -> 243243.44 | Q19: =Q18+2000 -> 8000 | R19: =T19*(1-$C$39) -> -2510555.5 | S19: =U19*(1-$C$39) -> -3161569.5 | T19: =V19-$N$23 -> -3659701.9 | U19: =W19-$O$23 -> -4608701.9 | V19: =Q19*$G$5 -> 6486491.6 | W19: =V19 -> 6486491.6 | X19: =R19/V19 -> -0.38704367 | Y19: =S19/W19 -> -0.48740825
B20: Natural Gas Power ($/cuft) | C20: =AVERAGE(37.96, 35.42, 41.31, 39.17, 34.88, 33.91, 38.79, 30.07, 31.63, 29.64, 20.36, 30.94)/1000 -> 0.033673333 | D20: Hawaii 2022/2023 industrial | F20: Total Land Area Used (m2) | G20: ='Sys Volume & Area'!F23 -> 318222.7 | H20: used to calculate system productivity | Q20: =Q19+2000 -> 10000 | R20: =T20*(1-$C$39) -> -1398122.2 | S20: =U20*(1-$C$39) -> -2049136.2 | T20: =V20-$N$23 -> -2038079 | U20: =W20-$O$23 -> -2987079 | V20: =Q20*$G$5 -> 8108114.5 | W20: =V20 -> 8108114.5 | X20: =R20/V20 -> -0.17243493 | Y20: =S20/W20 -> -0.2527266
B21: Diesel Power ($/L) | C21: 1.6 | D21: May 2022 prices $1.42 | F21: Evaporation Per day (% of volume) | G21: ='Water & Nutrient Calcs'!L5/G19 -> 0.083333333 | I21: Solar PV Needed (MW) | N21: Total Production Cost ($/year) | Q21: =Q20+5000 -> 15000 | R21: =T21*(1-$C$39) -> 1382961.1 | S21: =U21*(1-$C$39) -> 731947.09 | T21: =V21-$N$23 -> 2015978.3 | U21: =W21-$O$23 -> 1066978.3 | V21: =Q21*$G$5 -> 12162172 | W21: =V21 -> 12162172 | X21: =R21/V21 -> 0.11371004 | Y21: =S21/W21 -> 0.060182268
B22: CO2 ($/ton) | C22: 375 | D22: estimated June 2022 (DAC @ $250/ton) | F22: Electricity Used (MWh) | G22: =SUM('Inputs Overview'!E65,'Inoculum Overview'!E54,'Biomass Overview'!E50,'Harvesting Overview'!E57,'Drying Overview'!E54)/1000 -> 1996.5516 | H22: =G22*C19*1000 -> 803412.35 | I22: =G22/2146 -> 0.93035953 | N22: Low | O22: High | Q22: =Q21+5000 -> 20000 | R22: =T22*(1-$C$39) -> 4164044.4 | S22: =U22*(1-$C$39) -> 3513030.4 | T22: =V22-$N$23 -> 6070035.5 | U22: =W22-$O$23 -> 5121035.5 | V22: =Q22*$G$5 -> 16216229 | W22: =V22 -> 16216229 | X22: =R22/V22 -> 0.25678253 | Y22: =S22/W22 -> 0.2166367
B23: Potassium Nitrate ($/ton) | C23: 600 | D23: rough estimate from two sources (highly volatile) | F23: Natural Gas Used (cuft) | G23: ='Drying Overview'!E55 -> 469497.91 | H23: =G23*C20 -> 15809.56 | N23: =I45+N19 -> 10146194 | O23: =J45+O19 -> 11095194 | Q23: =Q22+5000 -> 25000 | R23: =T23*(1-$C$39) -> 6945127.7 | S23: =U23*(1-$C$39) -> 6294113.7 | T23: =V23-$N$23 -> 10124093 | U23: =W23-$O$23 -> 9175092.8 | V23: =Q23*$G$5 -> 20270286 | W23: =V23 -> 20270286 | X23: =R23/V23 -> 0.34262603 | Y23: =S23/W23 -> 0.31050936
B24: Diammonium Phosphate ($/ton) | C24: 600 | D24: rough estimate from two sources (highly volatile) | F24: Diesel Used (L) | G24: =SUM('Inputs Overview'!E66,'Inoculum Overview'!E55,'Biomass Overview'!E54,'Harvesting Overview'!E58) -> 17940.653 | H24: =G24*C21 -> 28705.045 | Q24: 29000 | R24: =T24*(1-$C$39) -> 9169994.3 | S24: =U24*(1-$C$39) -> 8518980.3 | T24: =V24-$N$23 -> 13367339 | U24: =W24-$O$23 -> 12418339 | V24: =Q24*$G$5 -> 23513532 | W24: =V24 -> 23513532 | X24: =R24/V24 -> 0.38998795 | Y24: =S24/W24 -> 0.36230117
B25: Other Micronutrients ($/ton) | C25: =C24 -> 600 | D25: complete guess this is same cost as other nutrients | F25: CO2 Produced from Diesel (tons) | G25: =G24*2.7/1000 -> 48.439763 | L25: Miscellaneous Variables for Assessing Scenarios | Q25: =Q24+5000 -> 34000 | R25: =T25*(1-$C$39) -> 11951078 | S25: =U25*(1-$C$39) -> 11300064 | T25: =V25-$N$23 -> 17421396 | U25: =W25-$O$23 -> 16472396 | V25: =Q25*$G$5 -> 27567589 | W25: =V25 -> 27567589 | X25: =R25/V25 -> 0.43351914 | Y25: =S25/W25 -> 0.40990394
B26: Water ($/m3) | C26: =average(20.62, 80)/3.78541/100 -> 0.13290502 | F26: CO2 Used (tons) | G26: ='Water & Nutrient Calcs'!P11 -> 6952.1444 | H26: =G26*C22 -> 2607054.1 | L26: Section | M26: CAPEX Factor | N26: OPEX Factor | Q26: =Q25+5000 -> 39000 | R26: =T26*(1-$C$39) -> 14732161 | S26: =U26*(1-$C$39) -> 14081147 | T26: =V26-$N$23 -> 21475453 | U26: =W26-$O$23 -> 20526453 | V26: =Q26*$G$5 -> 31621647 | W26: =V26 -> 31621647 | X26: =R26/V26 -> 0.46588848 | Y26: =S26/W26 -> 0.44530087
B27: Labor Cost ($/hr) | C27: 36.5 | D27: salary of $70k/yr | F27: Potassuim Nitrate Used (tons) | G27: ='Water & Nutrient Calcs'!P12 -> 126.41619 | H27: =G27*C23 -> 75849.715 | L27: Inputs Section | M27: 1 | N27: 1 | Q27: =Q26+5000 -> 44000 | R27: =T27*(1-$C$39) -> 17513244 | S27: =U27*(1-$C$39) -> 16862230 | T27: =V27-$N$23 -> 25529510 | U27: =W27-$O$23 -> 24580510 | V27: =Q27*$G$5 -> 35675704 | W27: =V27 -> 35675704 | X27: =R27/V27 -> 0.49090115 | Y27: =S27/W27 -> 0.47265305
F28: Diammonium Phosphate Used (tons) | G28: ='Water & Nutrient Calcs'!P13 -> 9.1264344 | H28: =G28*C24 -> 5475.8607 | L28: Biomass Section | M28: 1 | N28: 1 | Q28: =Q27+5000 -> 49000 | R28: =T28*(1-$C$39) -> 20294327 | S28: =U28*(1-$C$39) -> 19643313 | T28: =V28-$N$23 -> 29583568 | U28: =W28-$O$23 -> 28634568 | V28: =Q28*$G$5 -> 39729761 | W28: =V28 -> 39729761 | X28: =R28/V28 -> 0.5108092 | Y28: =S28/W28 -> 0.49442314
B29: Algae Composition Input Variables | F29: Water Used (m3) | G29: ='Water & Nutrient Calcs'!N5*C6 -> 1573638.3 | H29: =G29*C26 -> 209144.43 | L29: Inoculum Section | M29: 1 | N29: 1 | Q29: =Q28+10000 -> 59000 | R29: =T29*(1-$C$39) -> 25856494 | S29: =U29*(1-$C$39) -> 25205480 | T29: =V29-$N$23 -> 37691682 | U29: =W29-$O$23 -> 36742682 | V29: =Q29*$G$5 -> 47837876 | W29: =V29 -> 47837876 | X29: =R29/V29 -> 0.54050255 | Y29: =S29/W29 -> 0.5268938
B30: Element (Source) | C30: % of Biomass | F30: Operations Managers | G30: =SUM('Inputs Overview'!L43,'Inoculum Overview'!L44,'Biomass Overview'!L44,'Harvesting Overview'!L44,'Drying Overview'!L44) -> 5 | H30: =SUM('Inputs Overview'!N43,'Inoculum Overview'!N44,'Biomass Overview'!N44,'Harvesting Overview'!N44,'Drying Overview'!N44) -> 1095000 | L30: Harvesting Section | M30: 1 | N30: 1 | Q30: =Q29+10000 -> 69000 | R30: =T30*(1-$C$39) -> 31418661 | S30: =U30*(1-$C$39) -> 30767647 | T30: =V30-$N$23 -> 45799797 | U30: =W30-$O$23 -> 44850797 | V30: =Q30*$G$5 -> 55945990 | W30: =V30 -> 55945990 | X30: =R30/V30 -> 0.56158914 | Y30: =S30/W30 -> 0.54995267
B31: Carbon (CO2) | C31: 0.54 | D31: did not record source, should evaluate more thoroughly | F31: Equipment Engineers | G31: =SUM('Inputs Overview'!L44,'Inoculum Overview'!L45,'Biomass Overview'!L45,'Harvesting Overview'!L45,'Drying Overview'!L45) -> 7 | H31: =SUM('Inputs Overview'!N44,'Inoculum Overview'!N45,'Biomass Overview'!N45,'Harvesting Overview'!N45,'Drying Overview'!N45) -> 1277500 | L31: Drying Section | M31: 1 | N31: 1 | Q31: =Q30+10000 -> 79000 | R31: =T31*(1-$C$39) -> 36980827 | S31: =U31*(1-$C$39) -> 36329813 | T31: =V31-$N$23 -> 53907911 | U31: =W31-$O$23 -> 52958911 | V31: =Q31*$G$5 -> 64054105 | W31: =V31 -> 64054105 | X31: =R31/V31 -> 0.57733735 | Y31: =S31/W31 -> 0.56717385
B32: Nitrogen [(NH4)(NO3)] | C32: 0.018 | D32: did not record source, should evaluate more thoroughly | F32: Maintenance Supervisors | G32: =SUM('Inputs Overview'!L45,'Inoculum Overview'!L46,'Biomass Overview'!L46,'Harvesting Overview'!L46,'Drying Overview'!L46) -> 5 | H32: =SUM('Inputs Overview'!N45,'Inoculum Overview'!N46,'Biomass Overview'!N46,'Harvesting Overview'!N46,'Drying Overview'!N46) -> 730000 | L32: Totals | M32: 1 | N32: 1 | Q32: =Q31+10000 -> 89000 | R32: =T32*(1-$C$39) -> 42542994 | S32: =U32*(1-$C$39) -> 41891980 | T32: =V32-$N$23 -> 62016026 | U32: =W32-$O$23 -> 61067026 | V32: =Q32*$G$5 -> 72162219 | W32: =V32 -> 72162219 | X32: =R32/V32 -> 0.58954664 | Y32: =S32/W32 -> 0.5805251
B33: Phosporus [(NH3)2(HPO4)] | C33: 0.0022 | D33: did not record source, should evaluate more thoroughly | F33: Administrators | G33: =SUM('Inputs Overview'!L46,'Inoculum Overview'!L47,'Biomass Overview'!L47,'Harvesting Overview'!L47,'Drying Overview'!L47) -> 5 | H33: =SUM('Inputs Overview'!N46,'Inoculum Overview'!N47,'Biomass Overview'!N47,'Harvesting Overview'!N47,'Drying Overview'!N47) -> 365000 | L33: Harvesting & Drying | M33: 1 | N33: 1 | Q33: =Q32+10000 -> 99000 | R33: =T33*(1-$C$39) -> 48105160 | S33: =U33*(1-$C$39) -> 47454146 | T33: =V33-$N$23 -> 70124140 | U33: =W33-$O$23 -> 69175140 | V33: =Q33*$G$5 -> 80270334 | W33: =V33 -> 80270334 | X33: =R33/V33 -> 0.5992894 | Y33: =S33/W33 -> 0.59117913
B34: Other Micronutrients | C34: =C33*(C33/C32) -> 0.00026888889 | D34: currently just a guess | F34: Operators (low) | G34: =SUM('Inputs Overview'!L47,'Inoculum Overview'!L48,'Biomass Overview'!L48,'Harvesting Overview'!L48,'Drying Overview'!L48) -> 14 | H34: =SUM('Inputs Overview'!N47,'Inoculum Overview'!N48,'Biomass Overview'!N48,'Harvesting Overview'!N48,'Drying Overview'!N48) -> 1022000 | Q34: =Q33+20000 -> 119000 | R34: =T34*(1-$C$39) -> 59229493 | S34: =U34*(1-$C$39) -> 58578479 | T34: =V34-$N$23 -> 86340369 | U34: =W34-$O$23 -> 85391369 | V34: =Q34*$G$5 -> 96486563 | W34: =V34 -> 96486563 | X34: =R34/V34 -> 0.61386261 | Y34: =S34/W34 -> 0.60711541
F35: Operators (high) | G35: =SUM('Inputs Overview'!L49,'Inoculum Overview'!L50,'Biomass Overview'!L50,'Harvesting Overview'!L50,'Drying Overview'!L50) -> 28 | H35: =SUM('Inputs Overview'!N49,'Inoculum Overview'!N50,'Biomass Overview'!N50,'Harvesting Overview'!N50,'Drying Overview'!N50) -> 2044000 | Q35: =Q34+20000 -> 139000 | R35: =T35*(1-$C$39) -> 70353827 | S35: =U35*(1-$C$39) -> 69702813 | T35: =V35-$N$23 -> 1.025566e+08 | U35: =W35-$O$23 -> 1.016076e+08 | V35: =Q35*$G$5 -> 112702792 | W35: =V35 -> 112702792 | X35: =R35/V35 -> 0.62424209 | Y35: =S35/W35 -> 0.61846571
B36: Tax Input Variables | C36: Value | D36: Notes | Q36: =Q35+20000 -> 159000 | R36: =T36*(1-$C$39) -> 81478160 | S36: =U36*(1-$C$39) -> 80827146 | T36: =V36-$N$23 -> 1.1877283e+08 | U36: =W36-$O$23 -> 1.1782383e+08 | V36: =Q36*$G$5 -> 128919021 | W36: =V36 -> 128919021 | X36: =R36/V36 -> 0.63201038 | Y36: =S36/W36 -> 0.62696059
B37: Federal Tax Rate | C37: 0.25 | D37: 2023 US | F37: System Cost Outputs | Q37: =Q36+20000 -> 179000 | R37: =T37*(1-$C$39) -> 92602493 | S37: =U37*(1-$C$39) -> 91951479 | T37: =V37-$N$23 -> 1.3498906e+08 | U37: =W37-$O$23 -> 1.3404006e+08 | V37: =Q37*$G$5 -> 1.4513525e+08 | W37: =V37 -> 1.4513525e+08 | X37: =R37/V37 -> 0.63804274 | Y37: =S37/W37 -> 0.63355717
B38: State Tax Rate | C38: 0.064 | D38: 2023 Hawaii | F38: Section | G38: Capital Cost ($) | I38: Operation Cost ($/year) | Q38: =Q37+20000 -> 199000 | R38: =T38*(1-$C$39) -> 1.0372683e+08 | S38: =U38*(1-$C$39) -> 1.0307581e+08 | T38: =V38-$N$23 -> 1.5120529e+08 | U38: =W38-$O$23 -> 1.5025629e+08 | V38: =Q38*$G$5 -> 1.6135148e+08 | W38: =V38 -> 1.6135148e+08 | X38: =R38/V38 -> 0.64286257 | Y38: =S38/W38 -> 0.63882781
B39: Total | C39: =SUM(C37:C38) -> 0.314 | G39: Low | H39: High | I39: Low | J39: High | Q39: =Q38+50000 -> 249000 | R39: =T39*(1-$C$39) -> 1.3153766e+08 | S39: =U39*(1-$C$39) -> 1.3088664e+08 | T39: =V39-$N$23 -> 1.9174586e+08 | U39: =W39-$O$23 -> 1.9079686e+08 | V39: =Q39*$G$5 -> 2.0189205e+08 | W39: =V39 -> 2.0189205e+08 | X39: =R39/V39 -> 0.6515247 | Y39: =S39/W39 -> 0.64830014
F40: Inputs Section | G40: ='Sections Overview'!D5*M27 -> 7982976.3 | H40: ='Sections Overview'!E5*M27 -> 12385705 | I40: ='Sections Overview'!D9*N27 -> 3914943 | J40: ='Sections Overview'!E9*N27 -> 4133943 | L40: =AVERAGE(G40:H40) -> 10184341 | M40: =L40/1000000 -> 10.184341 | N40: =AVERAGE(I40:J40) -> 4024443 | O40: =N40/1000000 -> 4.024443 | Q40: =Q39+50000 -> 299000 | R40: =T40*(1-$C$39) -> 1.5934849e+08 | S40: =U40*(1-$C$39) -> 1.5869748e+08 | T40: =V40-$N$23 -> 2.3228643e+08 | U40: =W40-$O$23 -> 2.3133743e+08 | V40: =Q40*$G$5 -> 2.4243262e+08 | W40: =V40 -> 2.4243262e+08 | X40: =R40/V40 -> 0.6572898 | Y40: =S40/W40 -> 0.65460446
...

Sheet Sections Overview
B2: Costs | D2: Sections | N2: Total System
D3: Inputs | F3: Biomass | H3: Inoculum | J3: Harvesting | L3: Drying
D4: Low | E4: High | F4: Low | G4: High | H4: Low | I4: High | J4: Low | K4: High | L4: Low | M4: High | N4: Low | O4: High
B5: Capital Costs | D5: =SUM(D6:D8) -> 7982976.3 | E5: =SUM(E6:E8) -> 12385705 | F5: =SUM(F6:F8) -> 8922336.6 | G5: =SUM(G6:G8) -> 9188357 | H5: =SUM(H6:H8) -> 632835.16 | I5: =SUM(I6:I8) -> 634285.37 | J5: =SUM(J6:J8) -> 1919592.8 | K5: =SUM(K6:K8) -> 2284559.6 | ... M5: =SUM(M6:M8) -> 1732219.8 | N5: =sum(D5,F5,J5,L5) -> 20340826 | O5: =sum(E5,G5,K5,M5) -> 25590841
C6: Equipment Purchase | D6: ='Inputs Overview'!F17 -> 2892080.5 | E6: ='Inputs Overview'!F17 -> 2892080.5 | F6: ='Biomass Overview'!F8 -> 8889546 | G6: ='Biomass Overview'!F8 -> 8889546 | H6: ='Inoculum Overview'!O23 -> 632656.4 | I6: ='Inoculum Overview'!P23 -> 632656.4 | J6: ='Harvesting Overview'!F12 -> 695353.54 | K6: ='Harvesting Overview'!F12 -> 695353.54 | L6: ='Drying Overview'!E9 -> 402948.56 | M6: ='Drying Overview'!E9 -> 402948.56 | N6: =sum(D6,F6,J6,L6) -> 12879929 | O6: =sum(E6,G6,K6,M6) -> 12879929 | P6: =AVERAGE(N6:O6)/1000000 -> 12.879929 | Q6: =AVERAGE(D6:E6)/1000000 -> 2.8920805 | R6: =AVERAGE(F6:G6)/1000000 -> 8.889546 | S6: =AVERAGE(H6:I6)/1000000 -> 0.6326564 | T6: =AVERAGE(J6:K6)/1000000 -> 0.69535354 | U6: =AVERAGE(L6:M6)/1000000 -> 0.40294856
C7: Installation, Engr, & Other | D7: ='Inputs Overview'!N23-'Inputs Overview'!F17 -> 5090061.8 | E7: ='Inputs Overview'!O23-'Inputs Overview'!F17 -> 9486024.2 | F7: ='Biomass Overview'!O23-'Biomass Overview'!F8 -> 0 | G7: ='Biomass Overview'!P23-'Biomass Overview'!F8 -> 0 | H7: ='Inoculum Overview'!O23-'Inoculum Overview'!F9 -> 0 | I7: ='Inoculum Overview'!P23-'Inoculum Overview'!F9 -> 0 | J7: ='Harvesting Overview'!O23-'Harvesting Overview'!F12 -> 1223822.2 | K7: ='Harvesting Overview'!P23-'Harvesting Overview'!F12 -> 1585406.1 | L7: ='Drying Overview'!N23 -> 1112138 | M7: ='Drying Overview'!O23 -> 1321671.3 | N7: =sum(D7,F7,J7,L7) -> 7426022 | O7: =sum(E7,G7,K7,M7) -> 12393102 | P7: =AVERAGE(N7:O7)/1000000 -> 9.9095618 | Q7: =AVERAGE(D7:E7)/1000000 -> 7.288043 | R7: =AVERAGE(F7:G7)/1000000 -> 0 | S7: =AVERAGE(H7:I7)/1000000 -> 0 | T7: =AVERAGE(J7:K7)/1000000 -> 1.4046142 | U7: =AVERAGE(L7:M7)/1000000 -> 1.2169047
C8: Land | D8: ='Inputs Overview'!N34 -> 834 | E8: ='Inputs Overview'!N35 -> 7600 | F8: ='Biomass Overview'!O35 -> 32790.574 | G8: ='Biomass Overview'!O36 -> 298810.99 | H8: ='Inoculum Overview'!O35 -> 178.75785 | I8: ='Inoculum Overview'!O36 -> 1628.9684 | J8: ='Harvesting Overview'!O35 -> 417 | K8: ='Harvesting Overview'!O36 -> 3800 | L8: ='Drying Overview'!N35 -> 834 | M8: ='Drying Overview'!N36 -> 7600 | N8: =sum(D8,F8,J8,L8) -> 34875.574 | O8: =sum(E8,G8,K8,M8) -> 317810.99 | P8: =AVERAGE(N8:O8)/1000000 -> 0.17634328 | Q8: =AVERAGE(D8:E8)/1000000 -> 0.004217 | R8: =AVERAGE(F8:G8)/1000000 -> 0.16580078 | S8: =AVERAGE(H8:I8)/1000000 -> 0.00090386315 | T8: =AVERAGE(J8:K8)/1000000 -> 0.0021085 | U8: =AVERAGE(L8:M8)/1000000 -> 0.004217
B9: Operation Costs | D9: =SUM(D10:D13) -> 3914943 | E9: =SUM(E10:E13) -> 4133943 | F9: =SUM(F10:F13) -> 3488359.8 | G9: =SUM(G10:G13) -> 4072359.8 | H9: =SUM(H10:H13) -> 907762.84 | I9: =SUM(I10:I13) -> 980762.84 | J9: =SUM(J10:J13) -> 850191.42 | K9: =SUM(K10:K13) -> 850191.42 | ... M9: =SUM(M10:M13) -> 814693.09 | N9: =sum(D9,F9,J9,L9) -> 8995187.3 | O9: =sum(E9,G9,K9,M9) -> 9871187.3
C10: Materials / Inputs | D10: ='Inputs Overview'!E48 -> 2897919.5 | E10: ='Inputs Overview'!E48 -> 2897919.5 | F10: ='Biomass Overview'!E45 -> 0 | G10: ='Biomass Overview'!E45*2 -> 0 | H10: ='Inoculum Overview'!E45 -> 0 | I10: ='Inoculum Overview'!E45 -> 0 | J10: 0 | K10: 0 | L10: 0 | M10: 0 | N10: =sum(D10,F10,J10,L10) -> 2897919.5 | O10: =sum(E10,G10,K10,M10) -> 2897919.5 | P10: =AVERAGE(N10:O10)/1000000 -> 2.8979195 | Q10: =AVERAGE(D10:E10)/1000000 -> 2.8979195 | R10: =AVERAGE(F10:G10)/1000000 -> 0 | S10: =AVERAGE(H10:I10)/1000000 -> 0 | T10: =AVERAGE(J10:K10)/1000000 -> 0 | U10: =AVERAGE(L10:M10)/1000000 -> 0
C11: Energy | D11: ='Inputs Overview'!E64 -> 38504.531 | E11: ='Inputs Overview'!E64 -> 38504.531 | F11: ='Biomass Overview'!E52 -> 1656882.5 | G11: ='Biomass Overview'!E52 -> 1656882.5 | H11: ='Inoculum Overview'!E53 -> 130.02433 | I11: ='Inoculum Overview'!E53 -> 130.02433 | J11: ='Harvesting Overview'!E56 -> 121395.4 | K11: ='Harvesting Overview'!E56 -> 121395.4 | L11: ='Drying Overview'!E53 -> 21246.694 | M11: ='Drying Overview'!E53 -> 21246.694 | N11: =sum(D11,F11,J11,L11) -> 1838029.1 | O11: =sum(E11,G11,K11,M11) -> 1838029.1 | P11: =AVERAGE(N11:O11)/1000000 -> 1.8380291 | Q11: =AVERAGE(D11:E11)/1000000 -> 0.038504531 | R11: =AVERAGE(F11:G11)/1000000 -> 1.6568825 | S11: =AVERAGE(H11:I11)/1000000 -> 0.00013002433 | T11: =AVERAGE(J11:K11)/1000000 -> 0.1213954 | U11: =AVERAGE(L11:M11)/1000000 -> 0.021246694
C12: Maintenance | D12: ='Inputs Overview'!E82 -> 139018.97 | E12: ='Inputs Overview'!E82 -> 139018.97 | F12: ='Biomass Overview'!E60 -> 444477.3 | G12: ='Biomass Overview'!E60 -> 444477.3 | H12: ='Inoculum Overview'!E62 -> 31632.82 | I12: ='Inoculum Overview'!E62 -> 31632.82 | J12: ='Harvesting Overview'!E68 -> 35296.02 | K12: ='Harvesting Overview'!E68 -> 35296.02 | L12: ='Drying Overview'!E62 -> 26946.399 | M12: ='Drying Overview'!E62 -> 26946.399 | N12: =sum(D12,F12,J12,L12) -> 645738.69 | O12: =sum(E12,G12,K12,M12) -> 645738.69 | P12: =AVERAGE(N12:O12)/1000000 -> 0.64573869 | Q12: =AVERAGE(D12:E12)/1000000 -> 0.13901897 | R12: =AVERAGE(F12:G12)/1000000 -> 0.4444773 | S12: =AVERAGE(H12:I12)/1000000 -> 0.03163282 | T12: =AVERAGE(J12:K12)/1000000 -> 0.03529602 | U12: =AVERAGE(L12:M12)/1000000 -> 0.026946399
C13: Labor | D13: ='Inputs Overview'!N48 -> 839500 | E13: ='Inputs Overview'!N50 -> 1058500 | F13: ='Biomass Overview'!N49 -> 1387000 | G13: ='Biomass Overview'!N51 -> 1971000 | H13: ='Inoculum Overview'!N49 -> 876000 | I13: ='Inoculum Overview'!N51 -> 949000 | J13: ='Harvesting Overview'!N49 -> 693500 | K13: ='Harvesting Overview'!N51 -> 693500 | L13: ='Drying Overview'!N49 -> 693500 | M13: ='Drying Overview'!N51 -> 766500 | N13: =sum(D13,F13,J13,L13) -> 3613500 | O13: =sum(E13,G13,K13,M13) -> 4489500 | P13: =AVERAGE(N13:O13)/1000000 -> 4.0515 | Q13: =AVERAGE(D13:E13)/1000000 -> 0.949 | R13: =AVERAGE(F13:G13)/1000000 -> 1.679 | S13: =AVERAGE(H13:I13)/1000000 -> 0.9125 | T13: =AVERAGE(J13:K13)/1000000 -> 0.6935 | U13: =AVERAGE(L13:M13)/1000000 -> 0.73
P14: =SUM(P6:P13) -> 32.399021
B15: CAPEX & OPEX Percentages Breakdown | D15: Sections | N15: Total System
D16: Inputs | F16: Biomass | H16: Inoculum | J16: Harvesting | L16: Drying
D17: Low | E17: High | F17: Low | G17: High | H17: Low | I17: High | J17: Low | K17: High | L17: Low | M17: High | N17: Low | O17: High
B18: Capital Costs | D18: =SUM(D19:D21) -> 1 | E18: =SUM(E19:E21) -> 1 | F18: =SUM(F19:F21) -> 1 | G18: =SUM(G19:G21) -> 1 | H18: =SUM(H19:H21) -> 1 | I18: =SUM(I19:I21) -> 1 | J18: =SUM(J19:J21) -> 1 | K18: =SUM(K19:K21) -> 1 | ... O18: =SUM(O19:O21) -> 1
C19: Equipment Purchase | D19: =D6/D$5 -> 0.36228099 | E19: =E6/E$5 -> 0.23350149 | F19: =F6/F$5 -> 0.99632489 | G19: =G6/G$5 -> 0.96747939 | H19: =H6/H$5 -> 0.99971753 | I19: =I6/I$5 -> 0.99743181 | J19: =J6/J$5 -> 0.36224013 | K19: =K6/K$5 -> 0.30437093 | ... O19: =O6/O$5 -> 0.50330228
C20: Installation, Engr, & Other | D20: =D7/D$5 -> 0.63761454 | E20: =E7/E$5 -> 0.7658849 | F20: =F7/F$5 -> 0 | G20: =G7/G$5 -> 0 | H20: =H7/H$5 -> 0 | I20: =I7/I$5 -> 0 | J20: =J7/J$5 -> 0.63754263 | K20: =K7/K$5 -> 0.69396573 | ... O20: =O7/O$5 -> 0.48427879
C21: Land | D21: =D8/D$5 -> 0.00010447231 | E21: =E8/E$5 -> 0.00061361062 | F21: =F8/F$5 -> 0.0036751107 | G21: =G8/G$5 -> 0.032520612 | H21: =H8/H$5 -> 0.00028247143 | I21: =I8/I$5 -> 0.0025681949 | J21: =J8/J$5 -> 0.00021723358 | K21: =K8/K$5 -> 0.0016633403 | ... O21: =O8/O$5 -> 0.012418935
B22: Operation Costs | D22: =SUM(D23:D26) -> 1 | E22: =SUM(E23:E26) -> 1 | F22: =SUM(F23:F26) -> 1 | G22: =SUM(G23:G26) -> 1 | H22: =SUM(H23:H26) -> 1 | I22: =SUM(I23:I26) -> 1 | J22: =SUM(J23:J26) -> 1 | K22: =SUM(K23:K26) -> 1 | ... O22: =SUM(O23:O26) -> 1
C23: Materials / Inputs | D23: =D10/D$9 -> 0.7402201 | E23: =E10/E$9 -> 0.70100615 | F23: =F10/F$9 -> 0 | G23: =G10/G$9 -> 0 | H23: =H10/H$9 -> 0 | I23: =I10/I$9 -> 0 | J23: =J10/J$9 -> 0 | K23: =K10/K$9 -> 0 | ... O23: =O10/O$9 -> 0.29357355
C24: Energy | D24: =D11/D$9 -> 0.0098352726 | E24: =E11/E$9 -> 0.0093142386 | F24: =F11/F$9 -> 0.47497465 | G24: =G11/G$9 -> 0.40686053 | H24: =H11/H$9 -> 0.00014323601 | I24: =I11/I$9 -> 0.00013257469 | J24: =J11/J$9 -> 0.14278597 | K24: =K11/K$9 -> 0.14278597 | ... O24: =O11/O$9 -> 0.18620142
C25: Maintenance | D25: =D12/D$9 -> 0.035509833 | E25: =E12/E$9 -> 0.033628662 | F25: =F12/F$9 -> 0.12741728 | G25: =G12/G$9 -> 0.1091449 | H25: =H12/H$9 -> 0.034847009 | I25: =I12/I$9 -> 0.032253282 | J25: =J12/J$9 -> 0.04151538 | K25: =K12/K$9 -> 0.04151538 | ... O25: =O12/O$9 -> 0.065416517
C26: Labor | D26: =D13/D$9 -> 0.2144348 | E26: =E13/E$9 -> 0.25605094 | F26: =F13/F$9 -> 0.39760807 | G26: =G13/G$9 -> 0.48399457 | H26: =H13/H$9 -> 0.96500975 | I26: =I13/I$9 -> 0.96761414 | J26: =J13/J$9 -> 0.81569865 | K26: =K13/K$9 -> 0.81569865 | ... O26: =O13/O$9 -> 0.45480851
B28: Individual Costs Percentages Breakdown | D28: Sections | N28: Total System
D29: Inputs | F29: Biomass | H29: Inoculum | J29: Harvesting | L29: Drying
D30: Low | E30: High | F30: Low | G30: High | H30: Low | I30: High | J30: Low | K30: High | L30: Low | M30: High | N30: Low | O30: High
B31: Capital Costs | D31: =SUM(D32:D34) -> 0.39246077 | E31: =SUM(E32:E34) -> 0.48398975 | F31: =SUM(F32:F34) -> 0.4386418 | G31: =SUM(G32:G34) -> 0.35904865 | H31: =SUM(H32:H34) -> 0.031111576 | I31: =SUM(I32:I34) -> 0.02478564 | J31: =SUM(J32:J34) -> 0.094371426 | K31: =SUM(K32:K34) -> 0.089272549 | ... O31: =SUM(O32:O34) -> 1
C32: Equipment Purchase | D32: =D6/$N$5 -> 0.14218108 | E32: =E6/$O$5 -> 0.11301233 | F32: =F6/$N$5 -> 0.43702974 | G32: =G6/$O$5 -> 0.34737217 | H32: =H6/$N$5 -> 0.031102788 | I32: =I6/$O$5 -> 0.024721986 | J32: =J6/$N$5 -> 0.034185118 | K32: =K6/$O$5 -> 0.027171969 | L32: =L6/$N$5 -> 0.019809842 | M32: =M6/$O$5 -> 0.015745811 | N32: =sum(D32,F32,J32,L32) -> 0.63320578 | O32: =sum(E32,G32,K32,M32) -> 0.50330228
C33: Installation, Engr, & Other | D33: =D7/$N$5 -> 0.25023869 | E33: =E7/$O$5 -> 0.37068044 | F33: =F7/$N$5 -> 0 | G33: =G7/$O$5 -> 0 | H33: =H7/$N$5 -> 0 | I33: =I7/$O$5 -> 0 | J33: =J7/$N$5 -> 0.060165807 | K33: =K7/$O$5 -> 0.061952089 | L33: =L7/$N$5 -> 0.054675165 | M33: =M7/$O$5 -> 0.051646262 | N33: =sum(D33,F33,J33,L33) -> 0.36507966 | O33: =sum(E33,G33,K33,M33) -> 0.48427879
C34: Land | D34: =D8/$N$5 -> 4.1001284e-05 | E34: =E8/$O$5 -> 0.00029698125 | F34: =F8/$N$5 -> 0.0016120572 | G34: =G8/$O$5 -> 0.011676482 | H34: =H8/$N$5 -> 8.7881314e-06 | I34: =I8/$O$5 -> 6.3654353e-05 | J34: =J8/$N$5 -> 2.0500642e-05 | K34: =K8/$O$5 -> 0.00014849063 | L34: =L8/$N$5 -> 4.1001284e-05 | M34: =M8/$O$5 -> 0.00029698125 | N34: =sum(D34,F34,J34,L34) -> 0.0017145604 | O34: =sum(E34,G34,K34,M34) -> 0.012418935
B35: Operation Costs | D35: =SUM(D36:D39) -> 0.4352264 | E35: =SUM(E36:E39) -> 0.41878883 | F35: =SUM(F36:F39) -> 0.38780291 | G35: =SUM(G36:G39) -> 0.41255015 | H35: =SUM(H36:H39) -> 0.1009165 | I35: =SUM(I36:I39) -> 0.099356118 | J35: =SUM(J36:J39) -> 0.094516256 | K35: =SUM(K36:K39) -> 0.086128588 | ... O35: =SUM(O36:O39) -> 1
C36: Materials / Inputs | D36: =D10/$N$9 -> 0.32216333 | E36: =E10/$O$9 -> 0.29357355 | F36: =F10/$N$9 -> 0 | G36: =G10/$O$9 -> 0 | H36: =H10/$N$9 -> 0 | I36: =I10/$O$9 -> 0 | J36: =J10/$N$9 -> 0 | K36: =K10/$O$9 -> 0 | L36: =L10/$N$9 -> 0 | M36: =M10/$O$9 -> 0 | N36: =sum(D36,F36,J36,L36) -> 0.32216333 | O36: =sum(E36,G36,K36,M36) -> 0.29357355
C37: Energy | D37: =D11/$N$9 -> 0.0042805703 | E37: =E11/$O$9 -> 0.0039006991 | F37: =F11/$N$9 -> 0.18419655 | G37: =G11/$O$9 -> 0.16785037 | H37: =H11/$N$9 -> 1.4454878e-05 | I37: =I11/$O$9 -> 1.3172107e-05 | J37: =J11/$N$9 -> 0.013495595 | K37: =K11/$O$9 -> 0.012297954 | L37: =L11/$N$9 -> 0.0023620068 | M37: =M11/$O$9 -> 0.002152395 | N37: =sum(D37,F37,J37,L37) -> 0.20433472 | O37: =sum(E37,G37,K37,M37) -> 0.18620142
C38: Maintenance | D38: =D12/$N$9 -> 0.015454817 | E38: =E12/$O$9 -> 0.014083308 | F38: =F12/$N$9 -> 0.04941279 | G38: =G12/$O$9 -> 0.045027745 | H38: =H12/$N$9 -> 0.0035166383 | I38: =I12/$O$9 -> 0.0032045608 | J38: =J12/$N$9 -> 0.0039238783 | K38: =K12/$O$9 -> 0.003575661 | L38: =L12/$N$9 -> 0.0029956463 | M38: =M12/$O$9 -> 0.0027298033 | N38: =sum(D38,F38,J38,L38) -> 0.071787132 | O38: =sum(E38,G38,K38,M38) -> 0.065416517
C39: Labor | D39: =D13/$N$9 -> 0.093327685 | E39: =E13/$O$9 -> 0.10723128 | F39: =F13/$N$9 -> 0.15419357 | G39: =G13/$O$9 -> 0.19967203 | H39: =H13/$N$9 -> 0.09738541 | I39: =I13/$O$9 -> 0.096138385 | J39: =J13/$N$9 -> 0.077096783 | K39: =K13/$O$9 -> 0.070254974 | L39: =L13/$N$9 -> 0.077096783 | M39: =M13/$O$9 -> 0.077650234 | N39: =sum(D39,F39,J39,L39) -> 0.40171482 | O39: =sum(E39,G39,K39,M39) -> 0.45480851

Sheet Sys Volume & Area
B3: GROWTH SYSTEM VOLUME & LAND | L3: INOCULUM SYSTEM VOLUME & LAND
B5: General/Reference Dimensions for a Single Large Pond | L5: Inoculum Scaling Factor | M5: Time to Inocuate Large Ponds (wks) | N5: # of In. Ponds
B6: Size (acres) | C6: L:W Ratio | D6: Width (m) | E6: Length (m) | F6: Depth (m) | G6: SA (m2) | H6: Volume (m3) | I6: Col Space (m) | J6: Row Space (m)
B7: ='System Control & Outputs'!C7 -> 1 | C7: ='System Control & Outputs'!C9 -> 10 | D7: =sqrt((B7*4046.86)/C7) -> 20.116809 | E7: =D7*10 -> 201.16809 | F7: ='System Control & Outputs'!C8 -> 0.12 | G7: =(D7*(E7-D7))+((pi()/4)*D7^2) -> 3960.0136 | H7: =G7*F7 -> 475.20164 | I7: ='System Control & Outputs'!C10 -> 2.6 | J7: ='System Control & Outputs'!C11 -> 1.85 | L7: 10 | M7: 24 | N7: =ROUNDUP(B17/M7) -> 3
B9: Determining Total Volume of Large Ponds | L9: General/Reference Dimensions for a Single Inoculum Pond As
B10: Run Time (days/yr) | C10: BM Output (tons/yr) | D10: Steady-state Density (g/L) | E10: Growth Rate (/day) | F10: Biomass Production Rate | H10: Required Large Pond Volume | L10: Size (acres) | M10: L:W Ratio | N10: Width (m) | O10: Length (m) | P10: Depth (m) | Q10: SA (m2) | R10: Volume (m3) | S10: Col Space (m) | T10: Row Space (m) | U10: # of Columns | V10: # of Rows | W10: Land (acres) | X10: Land (m2)
F11: g/L/day | G11: g/L/yr | H11: L | I11: m3 | L11: =B7/L7 -> 0.1 | M11: =C7 -> 10 | N11: =sqrt((L11*4046.86)/M11) -> 6.3614935 | O11: =N11*10 -> 63.614935 | P11: =F7 -> 0.12 | Q11: =(N11*(O11-N11))+((pi()/4)*N11^2) -> 396.00136 | R11: =Q11*P11 -> 47.520164 | S11: =I7/2 -> 1.3 | T11: =J7/2 -> 0.925 | U11: =N7/V11 -> 2 | V11: =N7/2 -> 1.5 | W11: =(N11+S11)*(O11+T11)*$N$7/4046.86 -> 0.36655997 | X11: =W11*4046.86 -> 1483.4169
B12: ='System Control & Outputs'!C6 -> 330 | C12: ='System Control & Outputs'!C5 -> 800 | D12: ='System Control & Outputs'!C16 -> 0.362 | E12: ='System Control & Outputs'!C15 -> 0.207 | F12: =D12*E12 -> 0.074934 | G12: =F12*B12 -> 24.72822 | H12: =(C12*10^6)/G12 -> 32351702 | I12: =H12/1000 -> 32351.702
L13: General/Reference Dimensions for a Single Inoculum Pond Bs
L14: Size (acres) | M14: L:W Ratio | N14: Width (m) | O14: Length (m) | P14: Depth (m) | Q14: SA (m2) | R14: Volume (m3) | S14: Col Space (m) | T14: Row Space (m) | U14: # of Columns | V14: # of Rows | W14: Land (acres) | X14: Land (m2)
B15: Determining Number of Large Ponds | L15: =L11/$L$7 -> 0.01 | M15: =M11 -> 10 | N15: =sqrt((L15*4046.86)/M15) -> 2.0116809 | O15: =N15*10 -> 20.116809 | P15: =P11 -> 0.12 | Q15: =(N15*(O15-N15))+((pi()/4)*N15^2) -> 39.600136 | R15: =Q15*P15 -> 4.7520164 | S15: =S11 -> 1.3 | T15: =T11 -> 0.925 | U15: =U11 -> 2 | V15: =V11 -> 1.5 | W15: =(N15+S15)*(O15+T15)*$N$7/4046.86 -> 0.051657648 | X15: =W15*4046.86 -> 209.05127
B16: # of Large Ponds Required | C16: Number of Columns (n) | D16: Number of Rows (n) | E16: Final Number of Ponds
B17: =ROUNDUP(I12/H7) -> 69 | C17: =ROUNDDOWN(B17/D17) -> 1 | D17: =ROUNDUP(B17/2) -> 35 | E17: =B17 -> 69 | L17: General/Reference Dimensions for a Single Inoculum Pond Cs
C18: chosen randomly so the number of columns is closest to a whole number | E18: number of rows and columns not used | L18: Size (acres) | M18: L:W Ratio | N18: Width (m) | O18: Length (m) | P18: Depth (m) | Q18: SA (m2) | R18: Volume (m3) | S18: Col Space (m) | T18: Row Space (m) | U18: # of Columns | V18: # of Rows | W18: Land (acres) | X18: Land (m2)
L19: =L15/$L$7 -> 0.001 | M19: =M15 -> 10 | N19: =sqrt((L19*4046.86)/M19) -> 0.63614935 | O19: =N19*10 -> 6.3614935 | P19: =P15 -> 0.12 | Q19: =(N19*(O19-N19))+((pi()/4)*N19^2) -> 3.9600136 | R19: =Q19*P19 -> 0.47520164 | S19: =S15 -> 1.3 | T19: =T15 -> 0.925 | U19: =U15 -> 2 | V19: =V15 -> 1.5 | W19: =(N19+S19)*(O19+T19)*$N$7/4046.86 -> 0.010458286 | X19: =W19*4046.86 -> 42.323219
B20: Final Large Pond Info (Biomass Section)
B21: System Volume | D21: BM Output (tons/yr) | E21: Land Required (acres) | F21: Land Required (m2) | L21: Determining Total Volume & Size of Inoculum Pond As
B22: L | C22: m3 | L22: Run Time (days/yr) | M22: BM Output (tons/yr) | N22: Steady-state Density (g/L) | O22: Growth Rate (/day) | P22: Biomass Production Rate | R22: Large Pond Inoculation Density (g/L) | S22: Amount of Pond As to Drain
B23: =C23*1000 -> 32788913 | C23: =E17*H7 -> 32788.913 | D23: =B23*G12/10^6 -> 810.81145 | E23: =(D7+I7)*(E7+J7)*E17/4046.86 -> 78.634471 | F23: =E23*4046.86 -> 318222.7 | P23: g/L/day | Q23: g/L/yr
L24: 7 | M24: =Q24*R11*1000/(10^6)*$N$7 -> 0.074778395 | N24: =D12 -> 0.362 | O24: =E12 -> 0.207 | P24: =N24*O24 -> 0.074934 | Q24: =P24*L24 -> 0.524538 | R24: 0.05 | S24: 1
L26: Determining Total Volume & Size of Inoculum Pond Bs
B27: Calculating Total Large Pond Liner Required | E27: Value | L27: Run Time (days/yr) | M27: BM Output (tons/yr) | N27: Steady-state Density (g/L) | O27: Growth Rate (/day) | P27: Biomass Production Rate | R27: In. Pond As Inoculation Density (g/L) | S27: Amount of Pond Bs to Drain
B28: Bottom Surface Area of Each Pond (m2) | E28: =G7 -> 3960.0136 | P28: g/L/day | Q28: g/L/yr
B29: Flat Side Area of Each Pond (m2) | E29: =(E7-D7)*F7*2 -> 43.452307 | L29: =L24 -> 7 | M29: =Q29*R15*1000/(10^6)*$N$7 -> 0.0074778395 | N29: =N24 -> 0.362 | O29: =O24 -> 0.207 | P29: =N29*O29 -> 0.074934 | Q29: =P29*L29 -> 0.524538 | R29: 0.05 | S29: 1
B30: Round Side Area of Each Pond (m2) | E30: =pi()*D7*F7 -> 7.5838583
B31: Total Surface Area of Each Pond (m2) | E31: =SUM(E28:E30) -> 4011.0498 | L31: Determining Total Volume & Size of Inoculum Pond Cs
B32: Total Surface Area of All Ponds (m2) | E32: =E31*B17 -> 276762.44 | L32: Run Time (days/yr) | M32: BM Output (tons/yr) | N32: Steady-state Density (g/L) | O32: Growth Rate (/day) | P32: Biomass Production Rate | R32: In. Pond Bs Inoculation Density (g/L) | S32: Amount of Pond Cs to Drain
P33: g/L/day | Q33: g/L/yr
L34: =L29 -> 7 | M34: =Q34*R19*1000/(10^6)*$N$7 -> 0.00074778395 | N34: =N29 -> 0.362 | O34: =O29 -> 0.207 | P34: =N34*O34 -> 0.074934 | Q34: =P34*L34 -> 0.524538 | R34: 0.05 | S34: 1
L36: Calculating Total Pond As Liner Required | O36: Value
L37: Bottom Surface Area of Each Pond (m2) | O37: =Q11 -> 396.00136
L38: Flat Side Area of Each Pond (m2) | O38: =(O11-N11)*P11*2 -> 13.740826
L39: Round Side Area of Each Pond (m2) | O39: =pi()*N11*P11 -> 2.3982266
L40: Total Surface Area of Each Pond (m2) | O40: =SUM(O37:O39) -> 412.14042
L41: Total Surface Area of All Ponds (m2) | O41: =O40*$N$7 -> 1236.4213
L43: Calculating Total Pond Bs Liner Required | O43: Value
L44: Bottom Surface Area of Each Pond (m2) | O44: =Q15 -> 39.600136
L45: Flat Side Area of Each Pond (m2) | O45: =(O15-N15)*P15*2 -> 4.3452307
L46: Round Side Area of Each Pond (m2) | O46: =pi()*N15*P15 -> 0.75838583
L47: Total Surface Area of Each Pond (m2) | O47: =SUM(O44:O46) -> 44.703753
...

Sheet Water & Nutrient Calcs
B2: Calculating Water Demand
B3: Base transfer rate is determined by growth of ponds (daily transfer to harvesting), harvesting efficiency, and evaporation.
B4: Pond Size | C4: Total Volume (m3) | D4: Total Area (m2) | E4: Growth Rate (/day) | F4: Transfer to Harvesting (m3/day) | H4: Harvesting Efficiency | I4: Slurry Volume (m3/day) | K4: Evap Expected (mm/day) | L4: Evap Volume (m3/day) | N4: Water Used (m3/day)
B5: Large Ponds | C5: ='Sys Volume & Area'!C23 -> 32788.913 | D5: ='Sys Volume & Area'!G7*'Sys Volume & Area'!E17 -> 273240.94 | E5: ='Sys Volume & Area'!E12 -> 0.207 | F5: =C5*E5 -> 6787.305 | H5: 0.7 | I5: =F5*(1-H5) -> 2036.1915 | K5: 10 | L5: =(K5/1000)*D5 -> 2732.4094 | N5: =L5+I5 -> 4768.6009
B8: Calculating Nutrient Demand
B9: Nutrient demand is assumed to be directly correlated with growth rate and estimated based on biomass composition of the source elements (with efficiency & buffers accounted for)..
B10: Element | C10: Atomic Weight (g/mol) | D10: Source Molecule | E10: Molecular Formula | F10: Molecular Weight (g/mol) | H10: Element % of Biomass | I10: System Uptake Efficiency | K10: Molecule Demand (g/g BM) | L10: Source Molecule Consumption (tons/day) | N10: Nutrient Buffer | O10: Nutrients Used (tons/day) | P10: Nutrients Used (tons/yr) | Q10: Nutrients Used (kg/day) | R10: Nutrients Used (kg/yr)
B11: Carbon | C11: 12.0107 | D11: Carbon Dioxide | E11: (CO2) | F11: 44.01 | H11: ='System Control & Outputs'!C31 -> 0.54 | I11: 0.3 | K11: =H11*(F11/C11)/I11 -> 6.5956189 | L11: ='Sys Volume & Area'!$D$23*K11/'Sys Volume & Area'!$B$12 -> 16.205465 | N11: 0.3 | O11: =L11*(1+N11) -> 21.067104 | P11: =R11/1000 -> 6952.1444 | Q11: =O11*1000 -> 21067.104 | R11: =Q11*330 -> 6952144.4
B12: Nitrogen | C12: 14.0067 | D12: Potassium Nitrate | E12: (K)(NO3) | F12: 101.1032 | H12: ='System Control & Outputs'!C32 -> 0.018 | I12: 1 | K12: =H12*(F12/C12)/I12 -> 0.12992765 | L12: ='Sys Volume & Area'!$D$23*K12/'Sys Volume & Area'!$B$12 -> 0.31923281 | N12: 0.2 | O12: =L12*(1+N12) -> 0.38307937 | P12: =R12/1000 -> 126.41619 | Q12: =O12*1000 -> 383.07937 | R12: =Q12*330 -> 126416.19
B13: Phosphorus | C13: 30.973762 | D13: Diammonium Phosphate | E13: (NH4)2(PO4) | F13: 132.06 | H13: ='System Control & Outputs'!C33 -> 0.0022 | I13: 1 | K13: =H13*(F13/C13)/I13 -> 0.0093799391 | L13: ='Sys Volume & Area'!$D$23*K13/'Sys Volume & Area'!$B$12 -> 0.023046552 | N13: 0.2 | O13: =L13*(1+N13) -> 0.027655862 | P13: =R13/1000 -> 9.1264344 | Q13: =O13*1000 -> 27.655862 | R13: =Q13*330 -> 9126.4344
K15: Carbon Sequestration
K16: tons C per year | L16: =L11*I11*'System Control & Outputs'!C6 -> 1604.341
K17: tons CO2 per year | L17: =L16*C11/F11 -> 437.83818
K19: tons C per acre/yr | L19: =L16/'Sys Volume & Area'!$E$23 -> 20.402515
K20: tons CO2 per acre/yr | L20: =L17/'Sys Volume & Area'!$E$23 -> 5.5680184

Sheet Inputs Overview
B2: CAPITAL COSTS
B4: Equipment Direct Purchase Costs | J4: Equipment Total Capital Costs
B5: Eq # | C5: Name | D5: Cost ($/pc) | E5: Pcs/Pond | F5: Total Pcs | G5: Total Cost ($) | H5: % of Total | J5: Categories | L5: Multipliers | N5: Total Cost ($) | P5: % of Total
B6: 1 | C6: Tank 1 | D6: ='Inputs Details'!F7 -> 338333.01 | E6: ='Inputs Details'!I7/'Sys Volume & Area'!$E$17 -> 0.057971014 | F6: =E6*'Sys Volume & Area'!$E$17 -> 4 | G6: ='Inputs Details'!J7 -> 1353332.1 | H6: =G6/F$17 -> 0.46794411 | L6: Low | M6: Avg | N6: Low | O6: Avg | P6: Low | Q6: Avg
B7: =B6+1 -> 2 | C7: Pump 1 | D7: ='Inputs Details'!F11 -> 1345.713 | E7: ='Inputs Details'!I11/'Sys Volume & Area'!$E$17 -> 0.057971014 | F7: =E7*'Sys Volume & Area'!$E$17 -> 4 | G7: ='Inputs Details'!J11 -> 5382.852 | H7: =G7/F$17 -> 0.0018612386 | J7: Total Section Direct Cost | L7: - | M7: - | N7: =SUM(N8:N16) -> 6246894 | O7: =SUM(O8:O16)+N8 -> 10209044 | P7: =N7/N$23 -> 0.7826087 | Q7: =O7/O$23 -> 0.82476636
B8: =B7+1 -> 3 | C8: Filter 1 | D8: ='Inputs Details'!F15 -> 44345 | E8: =1/'Sys Volume & Area'!$E$17 -> 0.014492754 | F8: =E8*'Sys Volume & Area'!$E$17 -> 1 | G8: ='Inputs Details'!J15 -> 487795 | H8: =G8/F$17 -> 0.16866577 | K8: Eq. Purchase Cost | L8: - | M8: - | N8: =F17 -> 2892080.5 | P8: =N8/N$7 -> 0.46296296 | Q8: =N8/O$7 -> 0.28328612
B9: =B8+1 -> 4 | C9: Tank 2s | D9: ='Inputs Details'!E19 -> 238262.69 | E9: 0.5 | F9: =E9*'Sys Volume & Area'!$E$17 -> 34.5 | G9: ='Inputs Details'!J19 -> 338333.01 | H9: =G9/F$17 -> 0.11698603 | K9: Installation | L9: 0.2 | M9: 0.5 | N9: =L9*$N$8 -> 578416.11 | O9: =M9*$N$8 -> 1446040.3 | P9: =N9/N$7 -> 0.092592593 | Q9: =O9/O$7 -> 0.14164306
B10: =B9+1 -> 5 | C10: Pump 2s | D10: ='Inputs Details'!E23 -> - | E10: 0.5 | F10: =E10*'Sys Volume & Area'!$E$17 -> 34.5 | G10: ='Inputs Details'!J23 -> 1204.059 | H10: =G10/F$17 -> 0.00041632969 | K10: Process Piping | L10: 0.3 | M10: 0.4 | N10: =L10*$N$8 -> 867624.16 | O10: =M10*$N$8 -> 1156832.2 | P10: =N10/N$7 -> 0.13888889 | Q10: =O10/O$7 -> 0.11331445
B11: =B10+1 -> 6 | C11: Hopper 1s | D11: ='Inputs Details'!F27 -> 504 | E11: 0.5 | F11: =E11*'Sys Volume & Area'!$E$17 -> 34.5 | G11: ='Inputs Details'!J27 -> 17388 | H11: =G11/F$17 -> 0.0060122807 | K11: Instrumentation | L11: 0.2 | M11: 0.35 | N11: =L11*$N$8 -> 578416.11 | O11: =M11*$N$8 -> 1012228.2 | P11: =N11/N$7 -> 0.092592593 | Q11: =O11/O$7 -> 0.099150142
B12: =B11+1 -> 7 | C12: Hopper 2s | D12: ='Inputs Details'!F31 -> 117 | E12: 0.5 | F12: =E12*'Sys Volume & Area'!$E$17 -> 34.5 | G12: ='Inputs Details'!J31 -> 4036.5 | H12: =G12/F$17 -> 0.001395708 | K12: Insulation | L12: 0.01 | M12: 0.03 | N12: =L12*$N$8 -> 28920.805 | O12: =M12*$N$8 -> 86762.416 | P12: =N12/N$7 -> 0.0046296296 | Q12: =O12/O$7 -> 0.0084985836
B13: =B12+1 -> 8 | C13: Hopper 3s | D13: ='Inputs Details'!E35 -> - | E13: 0.5 | F13: =E13*'Sys Volume & Area'!$E$17 -> 34.5 | G13: ='Inputs Details'!J35 -> 1977.885 | H13: =G13/F$17 -> 0.00068389693 | K13: Electrical | L13: 0.1 | M13: 0.15 | N13: =L13*$N$8 -> 289208.05 | O13: =M13*$N$8 -> 433812.08 | P13: =N13/N$7 -> 0.046296296 | Q13: =O13/O$7 -> 0.042492918
B14: =B13+1 -> 9 | C14: Mix Tank 1s | D14: =SUM('Inputs Details'!E39:F39) -> 1467.19 | E14: 0.5 | F14: =E14*'Sys Volume & Area'!$E$17 -> 34.5 | G14: ='Inputs Details'!J39 -> 50618.055 | H14: =G14/F$17 -> 0.017502298 | K14: Buildings | L14: 0.1 | M14: 0.45 | N14: =L14*$N$8 -> 289208.05 | O14: =M14*$N$8 -> 1301436.2 | P14: =N14/N$7 -> 0.046296296 | Q14: =O14/O$7 -> 0.12747875
B15: =B14+1 -> 10 | C15: CO2 Tanks | D15: ='Inputs Details'!F43 -> 50000 | E15: ='Inputs Details'!I43/'Sys Volume & Area'!$E$17 -> 0.18319221 | F15: =E15*'Sys Volume & Area'!$E$17 -> 12.640262 | G15: =F15*D15 -> 632013.12 | H15: =G15/F$17 -> 0.21853234 | K15: Yard Improvement | L15: 0.05 | M15: 0.15 | N15: =L15*$N$8 -> 144604.03 | O15: =M15*$N$8 -> 433812.08 | P15: =N15/N$7 -> 0.023148148 | Q15: =O15/O$7 -> 0.042492918
B16: =B15+1 -> 11 | K16: Auxillary Facilities | L16: 0.2 | M16: 0.5 | N16: =L16*$N$8 -> 578416.11 | O16: =M16*$N$8 -> 1446040.3 | P16: =N16/N$7 -> 0.092592593 | Q16: =O16/O$7 -> 0.14164306
B17: Total Cost | F17: =SUM(G6:G16) -> 2892080.5 | J17: Total Section Indirect Cost | L17: - | M17: - | N17: =SUM(N18:N19) -> 1446040.3 | O17: =SUM(O18:O19) -> 1735248.3 | P17: =N17/N$23 -> 0.18115942 | Q17: =O17/O$23 -> 0.14018692
K18: Engineering | L18: 0.2 | M18: 0.25 | N18: =L18*$N$8 -> 578416.11 | O18: =M18*$N$8 -> 723020.14 | P18: =N18/N$17 -> 0.4 | Q18: =O18/O$17 -> 0.41666667
K19: Construction | L19: 0.3 | M19: 0.35 | N19: =L19*$N$8 -> 867624.16 | O19: =M19*$N$8 -> 1012228.2 | P19: =N19/N$17 -> 0.6 | Q19: =O19/O$17 -> 0.58333333
J20: Other | L20: - | M20: - | N20: =SUM(N21:N22) -> 289208.05 | O20: =SUM(O21:O22) -> 433812.08 | P20: =N20/N$23 -> 0.036231884 | Q20: =O20/O$23 -> 0.035046729
K21: Contractor's Fee | L21: 0.03 | M21: 0.05 | N21: =L21*$N$8 -> 86762.416 | O21: =M21*$N$8 -> 144604.03 | P21: =N21/N$20 -> 0.3 | Q21: =O21/O$20 -> 0.33333333
K22: Contingency | L22: 0.07 | M22: 0.1 | N22: =L22*$N$8 -> 202445.64 | O22: =M22*$N$8 -> 289208.05 | P22: =N22/N$20 -> 0.7 | Q22: =O22/O$20 -> 0.66666667
J23: Total Installation Cost | N23: =SUM(N7,N17,N20) -> 7982142.3 | O23: =SUM(O7,O17,O20) -> 12378105 | P23: - | Q23: -
J25: Calculating the Cost of Land
J26: System | L26: Acres
J27: Inputs | L27: 2 | M27: just a guess, assuming most of this is included in the biomass section
J29: Location | L29: Land Type | M29: Cost ($/acre) | N29: Total Cost ($)
J30: California | L30: Pasture | M30: 3010 | N30: =M30*L$27 -> 6020
J31: Arizona | L31: Farm | M31: 3800 | N31: =M31*L$27 -> 7600 | O31: pasture info not available
J32: New Mexico | L32: Pasture | M32: 417 | N32: =M32*L$27 -> 834
J33: Texas | L33: Pasture | M33: 1660 | N33: =M33*L$27 -> 3320
J34: Min Total | N34: =MIN(N30:N33) -> 834
J35: Max Total | N35: =MAX(N30:N33) -> 7600
B39: OPERATIONAL COSTS
B41: Materials/Inputs Costs | J41: Labor Expenditure | L41: currently best guess - not based references
B42: Mat # | C42: Name | D42: Cost ($/unit) | E42: Units (#/yr) | F42: Cost ($/yr) | G42: % of Total | J42: Labor | L42: # Needed | M42: Salary | N42: Wages ($/yr)
B43: 1 | C43: Water | D43: ='System Control & Outputs'!C26 -> 0.13290502 | E43: ='Water & Nutrient Calcs'!N5*'Sys Volume & Area'!B12 -> 1573638.3 | F43: =D43*E43 -> 209144.43 | G43: =F43/E$48 -> 0.072170547 | J43: Inputs Ops Managers | L43: 1 | M43: =M46*3 -> 219000 | N43: =M43*L43 -> 219000 | P43: =M43/(50*40) -> 109.5
B44: =B43+1 -> 2 | C44: CO2 | D44: ='System Control & Outputs'!C22 -> 375 | E44: ='Water & Nutrient Calcs'!O11*'Sys Volume & Area'!B12 -> 6952.1444 | F44: =D44*E44 -> 2607054.1 | G44: =F44/E$48 -> 0.8996296 | J44: Inputs Eq Engineers | L44: 1 | M44: =M46*2.5 -> 182500 | N44: =M44*L44 -> 182500 | P44: =M44/(50*40) -> 91.25
B45: =B44+1 -> 3 | C45: Ammonium Nitrate | D45: ='System Control & Outputs'!C23 -> 600 | E45: ='Water & Nutrient Calcs'!O12*'Sys Volume & Area'!B12 -> 126.41619 | F45: =D45*E45 -> 75849.715 | G45: =F45/E$48 -> 0.026173852 | J45: Inputs Maint Supervisors | L45: 1 | M45: =M46*2 -> 146000 | N45: =M45*L45 -> 146000 | P45: =M45/(50*40) -> 73
B46: =B45+1 -> 4 | C46: Diammonium Phosphate | D46: ='System Control & Outputs'!C24 -> 600 | E46: ='Water & Nutrient Calcs'!O13*'Sys Volume & Area'!B12 -> 9.1264344 | F46: =D46*E46 -> 5475.8607 | G46: =F46/E$48 -> 0.0018895834 | I46: calculated @ $20/hr | J46: Administrators | L46: 1 | M46: ='System Control & Outputs'!$C$27*40*50 -> 73000 | N46: =M46*L46 -> 73000 | O46: just a guess right now | P46: =M46/(50*40) -> 36.5
B47: =B46+1 -> 5 | C47: Other | D47: ='System Control & Outputs'!C25 -> 600 | E47: =E46*(E46/E45) -> 0.65886976 | F47: =D47*E47 -> 395.32186 | G47: =F47/E$48 -> 0.00013641575 | I47: calculated @ $20/hr | J47: Operators (low) | L47: 3 | M47: ='System Control & Outputs'!$C$27*40*50 -> 73000 | N47: =M47*L47 -> 219000 | O47: just a guess right now | P47: =M47/(50*40) -> 36.5
B48: Total Cost | E48: =SUM(F43:F47) -> 2897919.5 | J48: Total Labor | L48: =SUM(L43:L47) -> 7 | N48: =SUM(N43:N47) -> 839500
...

Sheet Inputs Details
L2: For Pumps | M2: Efficiencies
B3: EQUIPMENT DETAILS | M3: Pump | N3: Drive Train | O3: Motor | P3: MJ per kWh | Q3: MJ per L diesel
M4: 0.7 | N4: 0.95 | O4: 0.35 | P4: 3.6 | Q4: 38.4
B5: Tank 1 (holds unfiltered agricultural water, backs up for entire system)
B6: Buffer Stock (days) | C6: Available Capacity (m3) | D6: Type | E6: Cost 2006 | F6: Cost 2022 | H6: Required Capacity (m3) | I6: Units Required | J6: Total Purchase Cost | L6: Power Rating (kW) | M6: Run Time (hrs/yr) | N6: Electricity Use (kWh/yr) | O6: Base Operation Cost ($/yr)
B7: 3 | C7: 4000 | D7: Cone Roof | E7: =5700+700*(C7^0.7) -> 238262.69 | F7: =E7*1.42 -> 338333.01 | H7: =B7*'Water & Nutrient Calcs'!$N$5 -> 14305.803 | I7: =ROUNDUP(H7/C7) -> 4 | J7: =F7*I7 -> 1353332.1 | L7: 0 | M7: =B7*'Sys Volume & Area'!$B$12 -> 990 | N7: =L7*M7 -> 0 | O7: =N7*'System Control & Outputs'!$C$19 -> 0
B9: Pump 1 (every day transfers 1 day of water from Tank 1s, through Filter 1)
B10: Run Time (hrs/day) | C10: Available Flow Rating (L/s) | D10: Type | E10: Cost 2006 | F10: Cost 2022 | H10: Required Flow Rating (L/s) | I10: Units Required | J10: Total Purchase Cost | L10: Power Rating (kW) | M10: Run Time (hrs/yr) | N10: Diesel Fuel Use (L/yr) | O10: Base Operation Cost ($/yr)
B11: 12 | C11: =150000/3600 -> 41.666667 | D11: Vortex Impeller | E11: - | F11: =1900*'System Control & Outputs'!C49 -> 1345.713 | H11: =(H7/(B7*I7))*1000/(B11*60*60) -> 27.59607 | I11: =I7 -> 4 | J11: =F11*I11 -> 5382.852 | L11: =11*0.7457 -> 8.2027 | M11: =B11*'Sys Volume & Area'!$B$12 -> 3960 | N11: =(L11*M11)*($P$4/$Q$4)/($M$4*$N$4*$O$4) -> 13083.791 | O11: =N11*'System Control & Outputs'!$C$21 -> 20934.066
B13: Filter 1 (purifies water for use in the entire system)
B14: Run Time (hrs/day) | C14: Available Flow Rating (GPD) | D14: Type | E14: Cost 2006 | F14: Cost 2022 | H14: Required Flow Rating (GPD) | I14: Units Required | J14: Total Purchase Cost | L14: Power Rating (kW) | M14: Run Time (hrs/yr) | N14: Electricity Use (kWh/yr) | O14: Base Operation Cost ($/yr)
B15: 20 | C15: 40000 | D15: Ultrafiltration | E15: - | F15: 44345 | H15: =(($C$7/$B$7)*1000/(B15*60*60))*(3600/3.78541*24) -> 422675.48 | I15: =ROUNDUP(H15/C15) -> 11 | J15: =F15*I15 -> 487795 | L15: 6 | M15: =B15*'Sys Volume & Area'!$B$12 -> 6600 | N15: =L15*M15 -> 39600 | O15: =N15*'System Control & Outputs'!$C$19 -> 15935.04
B17: Tank 2s (holds filtered water, each backs up one row of ponds)
B18: Buffer Stock (days) | C18: Available Capacity (m3) | D18: Type | E18: Cost 2006 | F18: Cost 2022 | H18: Required Capacity (m3) | I18: Units Required | J18: Total Purchase Cost | L18: Power Rating (kW) | M18: Run Time (hrs/yr) | N18: Electricity Use (kWh/yr) | O18: Base Operation Cost ($/yr)
B19: 2 | C19: 4000 | D19: Cone Roof | E19: =5700+700*(C19^0.7) -> 238262.69 | F19: =E19*1.42 -> 338333.01 | H19: =B19*'Water & Nutrient Calcs'!N5/'Sys Volume & Area'!C17 -> 9537.2018 | I19: ='Sys Volume & Area'!C17 -> 1 | J19: =F19*I19 -> 338333.01 | L19: 0 | M19: 0 | N19: =L19*M19 -> 0 | O19: =N19*'System Control & Outputs'!$C$19 -> 0
B21: Pump 2s (transfers water from Tank 2s to Mix Tank 1s, where nutrients are dissolved)
B22: Run Time (hrs/day) | C22: Available Flow Rating (L/s) | D22: Type | E22: Cost 2006 | F22: Cost 2022 | H22: Required Flow Rating (L/s) | I22: Units Required | J22: Total Purchase Cost | L22: Power Rating (kW) | M22: Run Time (hrs/yr) | N22: Diesel Fuel Use (L/yr) | O22: Base Operation Cost ($/yr)
B23: 1 | C23: =96000/3600 -> 26.666667 | D23: - | E23: - | F23: =1700*'System Control & Outputs'!C49 -> 1204.059 | H23: =(H19/(B19*I19))*1000/(B23*60*60) -> 1324.6114 | I23: =I19 -> 1 | J23: =F23*I23 -> 1204.059 | L23: =10*0.7457 -> 7.457 | M23: =B23*'Sys Volume & Area'!$B$12 -> 330 | N23: =(L23*M23)*($P$4/$Q$4)/($M$4*$N$4*$O$4) -> 991.19629 | O23: =N23*'System Control & Outputs'!$C$21 -> 1585.9141
B25: Hopper 1s (holds powdered (K)(NO3), 1 hopper for every 2 ponds)
B26: Buffer Stock (days) | C26: Density (tons/m3) | D26: Available Capacity (gal) | E26: Cost 2006 | F26: Cost 2022 | H26: Required Capacity (gal) | I26: Units Required | J26: Total Purchase Cost | L26: Power Rating (kW) | M26: Run Time (hrs/yr) | N26: Electricity Use (kWh/yr) | O26: Base Operation Cost ($/yr)
B27: 30 | C27: 2.11 | D27: 160 | E27: - | F27: 504 | H27: ='Water & Nutrient Calcs'!O12*B27*1000/C27/I27*0.2641720524 -> 41.705692 | I27: ='Sys Volume & Area'!$E$17/2 -> 34.5 | J27: =F27*I27 -> 17388 | L27: 0 | M27: 0 | N27: =L27*M27 -> 0 | O27: =N27*'System Control & Outputs'!$C$19 -> 0
B29: Hopper 2s (holds powdered (NH4)2(PO4), 1 hopper for every 2 ponds)
B30: Buffer Stock (days) | C30: Density (tons/m3) | D30: Available Capacity (gal) | E30: Cost 2006 | F30: Cost 2022 | H30: Required Capacity (gal) | I30: Units Required | J30: Total Purchase Cost | L30: Power Rating (kW) | M30: Run Time (hrs/yr) | N30: Electricity Use (kWh/yr) | O30: Base Operation Cost ($/yr)
B31: 30 | C31: 1.62 | D31: 15 | E31: - | F31: 117 | H31: ='Water & Nutrient Calcs'!O13*B31*1000/C31/I31*0.2641720524 -> 3.9215812 | I31: =I27 -> 34.5 | J31: =F31*I31 -> 4036.5 | L31: 0 | M31: 0 | N31: =L31*M31 -> 0 | O31: =N31*'System Control & Outputs'!$C$19 -> 0
B33: Hopper 3s (holds other micronutrients, 1 hopper for every 2 ponds)
B34: Buffer Stock (days) | C34: Density (tons/m3) | D34: Available Capacity (gal) | E34: Cost 2006 | F34: Cost 2022 | H34: Required Capacity (gal) | I34: Units Required | J34: Total Purchase Cost | L34: Power Rating (kW) | M34: Run Time (hrs/yr) | N34: Electricity Use (kWh/yr) | O34: Base Operation Cost ($/yr)
B35: 30 | C35: =AVERAGE(C27,C31) -> 1.865 | D35: 3.5 | E35: - | F35: 57.33 | H35: =H31*(H31/H27) -> 0.36874581 | I35: =I31 -> 34.5 | J35: =F35*I35 -> 1977.885 | L35: 0 | M35: 0 | N35: =L35*M35 -> 0 | O35: =N35*'System Control & Outputs'!$C$19 -> 0
B37: Mix Tank 1s (used to dissolve nutrients in water, 1 tank for every 2 ponds)
B38: Run Time (hrs/day) | C38: Available Capacity (gal) | D38: Type | E38: Tank Cost | F38: Propeller Cost | G38: Cost 2022 | H38: Required Capacity (gal) | I38: Units Required | J38: Total Purchase Cost | L38: Power Rating (kW) | M38: Run Time (hrs/yr) | N38: Electricity Use (kWh/yr) | O38: Base Operation Cost ($/yr)
B39: 1 | C39: 510 | D39: Cone + Prop | E39: 890 | F39: 577.19 | G39: =E39+F39 -> 1467.19 | I39: =I35 -> 34.5 | J39: =G39*I39 -> 50618.055 | L39: =0.5*0.7457 -> 0.37285 | M39: =B39*'System Control & Outputs'!C$6 -> 330 | N39: =L39*M39 -> 123.0405 | O39: =N39*'System Control & Outputs'!$C$19 -> 49.511497
B41: CO2 Tanks (used to hold liquid CO2)
B42: Buffer Stock (days) | C42: Density (tons/m3) | D42: Available Capacity (m3) | E42: Cost 2006 | F42: Cost 2022 | H42: Required Capacity (m3) | I42: Units Required | J42: Total Purchase Cost | L42: Power Rating (kW) | M42: Run Time (hrs/yr) | N42: Electricity Use (kWh/yr) | O42: Base Operation Cost ($/yr)
B43: 30 | C43: 1.101 | D43: 50 | E43: - | F43: 50000 | H43: ='Water & Nutrient Calcs'!O11*B43 -> 632.01312 | I43: =H43/D43 -> 12.640262 | J43: =F43*I43 -> 632013.12 | L43: =0.5*0.7457 -> 0.37285 | M43: =B43*'System Control & Outputs'!C$6 -> 9900 | N43: =L43*M43 -> 3691.215 | O43: =N43*'System Control & Outputs'!$C$19 -> 1485.3449

Sheet Inoculum Overview
B2: CAPITAL COSTS
B4: Equipment Direct Purchase Costs | K4: Equipment Total Capital Costs
B5: Eq # | C5: Name | D5: Cost ($/pond) | E5: Pcs/Pond | F5: Total Pcs | G5: Total Cost ($) | H5: % of Total | K5: Categories | M5: Multipliers | O5: Total Cost ($) | Q5: % of Total
B6: 1 | C6: Pond As | D6: ='Inoculum Details'!L7 -> 74124.8 | E6: 1 | F6: ='Sys Volume & Area'!N7 -> 3 | G6: =F6*D6 -> 222374.4 | H6: =G6/F$9 -> 0.35149316 | M6: Low | N6: Avg | O6: Low | P6: Avg | Q6: Low | R6: Avg
B7: =B6+1 -> 2 | C7: Pond Bs | D7: ='Inoculum Details'!L8 -> 68653.88 | E7: 1 | F7: =F6 -> 3 | G7: =F7*D7 -> 205961.64 | H7: =G7/F$9 -> 0.32555055 | K7: Total Section Direct Cost | M7: - | N7: - | O7: =SUM(O8:O16) -> 632656.4 | P7: =SUM(P8:P16)+O8 -> 632656.4 | Q7: =O7/O$23 -> 1 | R7: =P7/P$23 -> 1
B8: =B7+1 -> 3 | C8: Pond Cs | D8: ='Inoculum Details'!L9 -> 68106.788 | E8: 1 | F8: =F7 -> 3 | G8: =F8*D8 -> 204320.36 | H8: =G8/F$9 -> 0.32295629 | L8: Eq. Purchase Cost | M8: - | N8: - | O8: =F9 -> 632656.4 | Q8: =O8/O$7 -> 1 | R8: =O8/P$7 -> 1
B9: Total Cost | F9: =SUM(G6:G9) -> 632656.4 | L9: Installation | M9: 0 | N9: 0 | O9: =M9*$O$8 -> 0 | P9: =N9*$O$8 -> 0 | Q9: =O9/O$7 -> 0 | R9: =P9/P$7 -> 0
L10: Process Piping | M10: 0 | N10: 0 | O10: =M10*$O$8 -> 0 | P10: =N10*$O$8 -> 0 | Q10: =O10/O$7 -> 0 | R10: =P10/P$7 -> 0
L11: Instrumentation | M11: 0 | N11: 0 | O11: =M11*$O$8 -> 0 | P11: =N11*$O$8 -> 0 | Q11: =O11/O$7 -> 0 | R11: =P11/P$7 -> 0
L12: Insulation | M12: 0 | N12: 0 | O12: =M12*$O$8 -> 0 | P12: =N12*$O$8 -> 0 | Q12: =O12/O$7 -> 0 | R12: =P12/P$7 -> 0
L13: Electrical | M13: 0 | N13: 0 | O13: =M13*$O$8 -> 0 | P13: =N13*$O$8 -> 0 | Q13: =O13/O$7 -> 0 | R13: =P13/P$7 -> 0
L14: Buildings | M14: 0 | N14: 0 | O14: =M14*$O$8 -> 0 | P14: =N14*$O$8 -> 0 | Q14: =O14/O$7 -> 0 | R14: =P14/P$7 -> 0
L15: Yard Improvement | M15: 0 | N15: 0 | O15: =M15*$O$8 -> 0 | P15: =N15*$O$8 -> 0 | Q15: =O15/O$7 -> 0 | R15: =P15/P$7 -> 0
L16: Auxillary Facilities | M16: 0 | N16: 0 | O16: =M16*$O$8 -> 0 | P16: =N16*$O$8 -> 0 | Q16: =O16/O$7 -> 0 | R16: =P16/P$7 -> 0
K17: Total Section Indirect Cost | M17: - | N17: - | O17: =SUM(O18:O19) -> 0 | P17: =SUM(P18:P19) -> 0 | Q17: =O17/O$23 -> 0 | R17: =P17/P$23 -> 0
L18: Engineering | M18: 0 | N18: 0 | O18: =M18*$O$8 -> 0 | P18: =N18*$O$8 -> 0 | Q18: =O18/O$17 -> #DIV/0! | R18: =P18/P$17 -> #DIV/0!
L19: Construction | M19: 0 | N19: 0 | O19: =M19*$O$8 -> 0 | P19: =N19*$O$8 -> 0 | Q19: =O19/O$17 -> #DIV/0! | R19: =P19/P$17 -> #DIV/0!
K20: Other | M20: - | N20: - | O20: =SUM(O21:O22) -> 0 | P20: =SUM(P21:P22) -> 0 | Q20: =O20/O$23 -> 0 | R20: =P20/P$23 -> 0
L21: Contractor's Fee | M21: 0 | N21: 0 | O21: =M21*$O$8 -> 0 | P21: =N21*$O$8 -> 0 | Q21: =O21/O$20 -> #DIV/0! | R21: =P21/P$20 -> #DIV/0!
L22: Contingency | M22: 0 | N22: 0 | O22: =M22*$O$8 -> 0 | P22: =N22*$O$8 -> 0 | Q22: =O22/O$20 -> #DIV/0! | R22: =P22/P$20 -> #DIV/0!
I23: =O8/O23 -> 1 | J23: =O8/P23 -> 1 | K23: Total Installation Cost | O23: =SUM(O7,O17,O20) -> 632656.4 | P23: =SUM(P7,P17,P20) -> 632656.4 | Q23: - | R23: -
K26: Calculating the Cost of Land
K27: System | M27: Acres
K28: Ponds | M28: =SUM('Sys Volume & Area'!W11,'Sys Volume & Area'!W15,'Sys Volume & Area'!W19) -> 0.42867591
K30: Location | M30: Land Type | N30: Cost ($/acre) | O30: Total Cost ($)
K31: California | M31: Pasture | N31: 3010 | O31: =N31*(M$28+M$29) -> 1290.3145
K32: Arizona | M32: Farm | N32: 3800 | O32: =N32*(M$28+M$29) -> 1628.9684 | P32: pasture info not available
K33: New Mexico | M33: Pasture | N33: 417 | O33: =N33*(M$28+M$29) -> 178.75785
K34: Texas | M34: Pasture | N34: 1660 | O34: =N34*(M$28+M$29) -> 711.60201
K35: Min Total | O35: =MIN(O31:O34) -> 178.75785
K36: Max Total | O36: =MAX(O31:O34) -> 1628.9684
B40: OPERATIONAL COSTS
B42: Materials/Inputs Costs | J42: Labor Expenditure | M42: Total Acres | N42: =M28 -> 0.42867591
B43: Mat # | C43: Name | D43: Cost ($/rplcmnt) | E43: Lifetime (yrs) | F43: Cost ($/yr) | G43: % of Total | J43: Labor | L43: # Needed | M43: Salary | N43: Wages ($/yr)
J44: Inoc. Ops Managers | L44: 1 | M44: =M47*3 -> 219000 | N44: =M44*L44 -> 219000
B45: Total Cost | E45: =SUM(F44) -> 0 | J45: Inoc. Eq Engineers | L45: 2 | M45: =M47*2.5 -> 182500 | N45: =M45*L45 -> 365000
J46: Inoc. Maint Supervisors | L46: 1 | M46: =M47*2 -> 146000 | N46: =M46*L46 -> 146000
I47: calculated @ $20/hr | J47: Administrators | L47: 1 | M47: ='System Control & Outputs'!$C$27*40*50 -> 73000 | N47: =M47*L47 -> 73000 | O47: just a guess right now
